Workbook

Sheet Instrucciones
B1: E1 · Catálogo de casos de prueba y matriz de trazabilidad · Sierra Alta
B2: Pruebas de Software · Proyecto Nuclear · Sistema web de pronóstico de producción (Sierra Alta S.A.S. BIC, marca Eleven Pro) · Corte 1 (23/10/2026)
B4: QUÉ ES ESTE ARCHIVO
B5: Anexo A del plan maestro (catálogo de casos) y entregable E1.2 (matriz de trazabilidad) del sistema web de pronóstico de producción. Los requisitos salen del documento de arquitectura (18/10/2026) y del contrato de la API; los resultados son los de la ejecución del 22/10/2026 contra el backend.
B7: HOJAS
B8: Requisitos → 11 funcionales y 5 no funcionales, agrupados en los módulos del monolito: autenticación, históricos, pronóstico, indicadores y transversal.
B9: Catalogo → 34 casos de prueba con datos, pasos, resultado esperado y resultado obtenido en la ejecución.
B10: Verificacion → compara el valor del sistema con el cálculo de referencia y decide APROBADO / FALLIDO con la tolerancia 0,01.
B11: Calculo_Referencia → cálculo independiente del promedio móvil de 2 periodos, MAD y MAPE sobre las series A y B.
B12: Matriz → qué casos verifican cada requisito y en qué estado está cada uno.
B13: Cobertura → % de requisitos cubiertos, mínimo de casos y veredictos. Se calcula sola.
B14: Riesgos → exposición = probabilidad × impacto, con los casos que responden a cada riesgo.
... B37: • Las series A, B y C son sintéticas. Datos reales de la empresa solo anonimizados (Ley 1581 de 2012).

Sheet Requisitos
A1: Requisitos del sistema web de pronóstico de producción (Sierra Alta)
A2: Requisitos tomados del documento de arquitectura (18/10/2026) y del contrato de la API (docs/architecture/api.md). Las reglas marcadas como propuesta se validan con Industrial. La Matriz y la Cobertura se alimentan de esta hoja.
A4: ID requisito | B4: Descripción | C4: Módulo | D4: Tipo | E4: Prioridad
A5: RF-01 | B5: Iniciar y cerrar sesión con usuario y contraseña; cuentas administradas, sin autorregistro. Clave errónea, usuario inexistente y cuenta inactiva reciben el mismo mensaje | C5: Autenticación y roles | D5: Funcional | E5: Alta
A6: RF-02 | B6: Administrar cuentas (solo el administrador): crear, desactivar o reactivar y asignar el rol; el administrador no puede desactivarse ni quitarse el rol a sí mismo | C6: Autenticación y roles | D6: Funcional | E6: Alta
A7: RF-03 | B7: Autorizar cada operación en el servidor según el alcance de cada rol (administrador, planeador de producción, supervisor de línea, analista de datos), con denegación por defecto | C7: Autenticación y roles | D7: Funcional | E7: Alta
A8: RF-04 | B8: Registrar eventos de seguridad (inicio y cierre de sesión, accesos denegados, CSRF rechazado, cambios de cuentas) sin contraseñas ni tokens | C8: Autenticación y roles | D8: Funcional | E8: Media
A9: RF-05 | B9: Consultar los productos y la serie mensual de cada uno, ordenada por periodo | C9: Históricos | D9: Funcional | E9: Alta
A10: RF-06 | B10: Cargar observaciones mensuales validando el lote: valor no negativo, una por serie y periodo, periodo normalizado al primer día del mes y sin convertir datos ausentes en cero | C10: Históricos | D10: Funcional | E10: Alta
A11: RF-07 | B11: Calcular el pronóstico por promedio móvil simple de 2 periodos usando solo periodos anteriores; exige al menos 2 observaciones consecutivas | C11: Pronóstico | D11: Funcional | E11: Alta
A12: RF-08 | B12: Conservar en cada ejecución las entradas usadas, los parámetros, el autor y la fecha, guardados de forma atómica, para explicar el resultado aunque el histórico se corrija | C12: Pronóstico | D12: Funcional | E12: Alta
A13: RF-09 | B13: Consultar las ejecuciones de pronóstico y el detalle de cada una | C13: Pronóstico | D13: Funcional | E13: Media
A14: RF-10 | B14: Calcular MAD (promedio de los errores absolutos) sobre los pares real–pronosticado | C14: Indicadores | D14: Funcional | E14: Alta
A15: RF-11 | B15: Calcular MAPE sobre los pares con valor real distinto de cero, informar los pares excluidos y reportar "no calculable" si no queda ninguno | C15: Indicadores | D15: Funcional | E15: Alta
... A20: RNF-05 | B20: Usabilidad: el usuario identifica producto, periodo y unidad, distingue valores reales de estimados y ve cada error junto a su campo | C20: Transversal | D20: No funcional | E20: Media

Sheet Calculo_Referencia
A1: Cálculo de referencia: promedio móvil de 2 periodos, MAD y MAPE
A2: Valor esperado independiente del sistema. Azul = datos de entrada; negro = fórmulas. Cada pronóstico usa solo los dos valores reales anteriores; MAPE excluye los pares con real = 0.
A4: Período t | B4: Serie A · demanda real | C4: MA(2) pronóstico | D4: Error | E4: |Error| | F4: ¿Entra en MAPE? (real ≠ 0) | G4: |Error| / Real | I4: Período t | J4: Serie B · demanda real | K4: MA(2) pronóstico | L4: Error | M4: |Error| | N4: ¿Entra en MAPE? (real ≠ 0) | O4: |Error| / Real | Q4: Parámetros | R4: Valor
A5: 1 | B5: 100 | I5: 1 | J5: 50 | Q5: Ventana del promedio móvil (periodos) | R5: 2
A6: 2 | B6: 120 | I6: 2 | J6: 70 | Q6: Tolerancia propuesta (unidades y puntos %) | R6: 0.01
A7: 3 | B7: 110 | C7: =AVERAGE(B5:B6) | D7: =B7-C7 | E7: =ABS(D7) | F7: =IF(B7<>0,1,0) | G7: =IF(F7=1,E7/B7,"") | I7: 3 | J7: 0 | K7: =AVERAGE(J5:J6) | L7: =J7-K7 | M7: =ABS(L7) | N7: =IF(J7<>0,1,0) | O7: =IF(N7=1,M7/J7,"") | Q7: La ventana está fija en 2 en las fórmulas de las columnas C y K (informativo).
A8: 4 | B8: 130 | C8: =AVERAGE(B6:B7) | D8: =B8-C8 | E8: =ABS(D8) | F8: =IF(B8<>0,1,0) | G8: =IF(F8=1,E8/B8,"") | I8: 4 | J8: 80 | K8: =AVERAGE(J6:J7) | L8: =J8-K8 | M8: =ABS(L8) | N8: =IF(J8<>0,1,0) | O8: =IF(N8=1,M8/J8,"")
A9: 5 | C9: =AVERAGE(B7:B8) | I9: 5 | J9: 60 | K9: =AVERAGE(J7:J8) | L9: =J9-K9 | M9: =ABS(L9) | N9: =IF(J9<>0,1,0) | O9: =IF(N9=1,M9/J9,"") | Q9: Resumen (valores de referencia) | R9: Valor
I10: 6 | K10: =AVERAGE(J8:J9) | Q10: Serie A · MAD | R10: =AVERAGE(E7:E8)
Q11: Serie A · MAPE (%) | R11: =IF(SUM(F7:F8)=0,"No calculable",AVERAGE(G7:G8)*100)
Q12: Serie A · pares usados / excluidos en MAPE | R12: =SUM(F7:F8)&" / "&(COUNT(F7:F8)-SUM(F7:F8))
Q13: Serie A · estimación periodo 5 | R13: =C9
A14: Cómo leerlo: cambia una demanda (azul) y todo se recalcula. Serie A = ejemplo del documento de arquitectura (pronósticos 110 y 115, estimación 120, MAD 7,50, MAPE 5,769231 %). Serie B = serie sintética con un real igual a 0 para probar la exclusión en MAPE. | Q14: Serie B · MAD | R14: =AVERAGE(M7:M9)
A15: Convención propuesta (pendiente de aprobación de Industrial): el pronóstico del periodo t es el promedio de los reales t−1 y t−2; el último pronóstico es una estimación futura sin error calculable; MAPE excluye los pares con real = 0 y, si no queda ninguno, es "no calculable". Serie C (0, 0, 0) se usa en CP-011: MAD = 0 y MAPE no calculable. | Q15: Serie B · MAPE (%) | R15: =IF(SUM(N7:N9)=0,"No calculable",AVERAGE(O7:O9)*100)
Q16: Serie B · pares usados / excluidos en MAPE | R16: =SUM(N7:N9)&" / "&(COUNT(N7:N9)-SUM(N7:N9))
Q17: Serie B · pronóstico periodo 4 | R17: =K8
Q18: Serie B · estimación periodo 6 | R18: =K10

Sheet Catalogo
A1: Catálogo de casos de prueba (Anexo A del plan maestro)
A2: Un caso por fila. Módulo se completa según el requisito. CP-001 a CP-009 toman su veredicto de la hoja Verificacion. Ejecución: 22/10/2026 contra el backend en el commit de trabajo actual.
A4: ID caso | B4: ID requisito | C4: Módulo (auto) | D4: Nivel | E4: Técnica | F4: Prioridad | G4: Precondiciones | H4: Datos de entrada | I4: Pasos | J4: Resultado esperado | K4: Tolerancia | L4: Resultado obtenido | M4: Veredicto | N4: Defecto asociado | O4: Ejecutor | P4: Fecha
A5: CP-001 | B5: RF-07 | C5: =IF(B5="","",IFERROR(INDEX(Requisitos!$C$5:$C$60,MATCH(B5,Requisitos!$A$5:$A$60,0)),"¿Requisito no existe?")) | D5: Unitaria | E5: Verificación numérica | F5: Alta | G5: Serie A cargada (4 meses) | H5: Serie A: 100, 120, 110, 130; método MA; ventana 2 | I5: Ejecutar pronóstico MA(2) | J5: Pronóstico del periodo 3 = 110,00 | K5: 0.01 | L5: No ejecutable: el servidor responde 501 Not Implemented (función pendiente de reglas de Industrial) | M5: =IFERROR(INDEX(Verificacion!$H$5:$H$24,MATCH(A5,Verificacion!$A$5:$A$24,0)),"PENDIENTE") | O5: Script API | P5: 22/10/2026
A6: CP-002 | B6: RF-07 | C6: =IF(B6="","",IFERROR(INDEX(Requisitos!$C$5:$C$60,MATCH(B6,Requisitos!$A$5:$A$60,0)),"¿Requisito no existe?")) | D6: Unitaria | E6: Verificación numérica | F6: Alta | G6: Ídem CP-001 | H6: Ídem CP-001 | I6: Ejecutar pronóstico MA(2) | J6: Pronóstico del periodo 4 = 115,00 | K6: 0.01 | L6: No ejecutable: el servidor responde 501 Not Implemented (función pendiente de reglas de Industrial) | M6: =IFERROR(INDEX(Verificacion!$H$5:$H$24,MATCH(A6,Verificacion!$A$5:$A$24,0)),"PENDIENTE") | O6: Script API | P6: 22/10/2026
A7: CP-003 | B7: RF-07 | C7: =IF(B7="","",IFERROR(INDEX(Requisitos!$C$5:$C$60,MATCH(B7,Requisitos!$A$5:$A$60,0)),"¿Requisito no existe?")) | D7: Unitaria | E7: Verificación numérica | F7: Alta | G7: Ídem CP-001 | H7: Ídem CP-001 | I7: Ejecutar pronóstico MA(2) | J7: Estimación futura del periodo 5 = 120,00, sin error calculable | K7: 0.01 | L7: No ejecutable: el servidor responde 501 Not Implemented (función pendiente de reglas de Industrial) | M7: =IFERROR(INDEX(Verificacion!$H$5:$H$24,MATCH(A7,Verificacion!$A$5:$A$24,0)),"PENDIENTE") | O7: Script API | P7: 22/10/2026
A8: CP-004 | B8: RF-10 | C8: =IF(B8="","",IFERROR(INDEX(Requisitos!$C$5:$C$60,MATCH(B8,Requisitos!$A$5:$A$60,0)),"¿Requisito no existe?")) | D8: Unitaria | E8: Verificación numérica | F8: Alta | G8: Ídem CP-001 | H8: Ídem CP-001 | I8: Calcular MAD sobre los periodos 3 y 4 | J8: MAD = 7,50 | K8: 0.01 | L8: No ejecutable: el servidor responde 501 Not Implemented (función pendiente de reglas de Industrial) | M8: =IFERROR(INDEX(Verificacion!$H$5:$H$24,MATCH(A8,Verificacion!$A$5:$A$24,0)),"PENDIENTE") | O8: Script API | P8: 22/10/2026
A9: CP-005 | B9: RF-11 | C9: =IF(B9="","",IFERROR(INDEX(Requisitos!$C$5:$C$60,MATCH(B9,Requisitos!$A$5:$A$60,0)),"¿Requisito no existe?")) | D9: Unitaria | E9: Verificación numérica | F9: Alta | G9: Ídem CP-001 | H9: Ídem CP-001 | I9: Calcular MAPE sobre los periodos 3 y 4 | J9: MAPE = 5,77 % (5,769231 %), 2 pares usados y 0 excluidos | K9: 0.01 | L9: No ejecutable: el servidor responde 501 Not Implemented (función pendiente de reglas de Industrial) | M9: =IFERROR(INDEX(Verificacion!$H$5:$H$24,MATCH(A9,Verificacion!$A$5:$A$24,0)),"PENDIENTE") | O9: Script API | P9: 22/10/2026
A10: CP-006 | B10: RF-07 | C10: =IF(B10="","",IFERROR(INDEX(Requisitos!$C$5:$C$60,MATCH(B10,Requisitos!$A$5:$A$60,0)),"¿Requisito no existe?")) | D10: Unitaria | E10: Verificación numérica | F10: Alta | G10: Serie B cargada (5 meses) | H10: Serie B: 50, 70, 0, 80, 60; método MA; ventana 2 | I10: Ejecutar pronóstico MA(2) | J10: Pronóstico del periodo 4 = 35,00 | K10: 0.01 | L10: No ejecutable: el servidor responde 501 Not Implemented (función pendiente de reglas de Industrial) | M10: =IFERROR(INDEX(Verificacion!$H$5:$H$24,MATCH(A10,Verificacion!$A$5:$A$24,0)),"PENDIENTE") | O10: Script API | P10: 22/10/2026
A11: CP-007 | B11: RF-10 | C11: =IF(B11="","",IFERROR(INDEX(Requisitos!$C$5:$C$60,MATCH(B11,Requisitos!$A$5:$A$60,0)),"¿Requisito no existe?")) | D11: Unitaria | E11: Verificación numérica | F11: Alta | G11: Ídem CP-006 | H11: Ídem CP-006 | I11: Calcular MAD sobre los periodos 3 a 5 | J11: MAD = 41,67 | K11: 0.01 | L11: No ejecutable: el servidor responde 501 Not Implemented (función pendiente de reglas de Industrial) | M11: =IFERROR(INDEX(Verificacion!$H$5:$H$24,MATCH(A11,Verificacion!$A$5:$A$24,0)),"PENDIENTE") | O11: Script API | P11: 22/10/2026
A12: CP-008 | B12: RF-11 | C12: =IF(B12="","",IFERROR(INDEX(Requisitos!$C$5:$C$60,MATCH(B12,Requisitos!$A$5:$A$60,0)),"¿Requisito no existe?")) | D12: Unitaria | E12: Verificación numérica | F12: Alta | G12: Ídem CP-006 | H12: Ídem CP-006 (el real del periodo 3 es 0) | I12: Calcular MAPE sobre los periodos 3 a 5 | J12: MAPE = 44,79 %, 2 pares usados y 1 excluido (real = 0) | K12: 0.01 | L12: No ejecutable: el servidor responde 501 Not Implemented (función pendiente de reglas de Industrial) | M12: =IFERROR(INDEX(Verificacion!$H$5:$H$24,MATCH(A12,Verificacion!$A$5:$A$24,0)),"PENDIENTE") | O12: Script API | P12: 22/10/2026
A13: CP-009 | B13: RF-07 | C13: =IF(B13="","",IFERROR(INDEX(Requisitos!$C$5:$C$60,MATCH(B13,Requisitos!$A$5:$A$60,0)),"¿Requisito no existe?")) | D13: Unitaria | E13: Verificación numérica | F13: Alta | G13: Ídem CP-006 | H13: Ídem CP-006 | I13: Ejecutar pronóstico MA(2) | J13: Estimación futura del periodo 6 = 70,00 | K13: 0.01 | L13: No ejecutable: el servidor responde 501 Not Implemented (función pendiente de reglas de Industrial) | M13: =IFERROR(INDEX(Verificacion!$H$5:$H$24,MATCH(A13,Verificacion!$A$5:$A$24,0)),"PENDIENTE") | O13: Script API | P13: 22/10/2026
A14: CP-010 | B14: RF-07 | C14: =IF(B14="","",IFERROR(INDEX(Requisitos!$C$5:$C$60,MATCH(B14,Requisitos!$A$5:$A$60,0)),"¿Requisito no existe?")) | D14: Unitaria | E14: Valores límite | F14: Alta | G14: Serie con una sola observación | H14: Serie: 100 | I14: Ejecutar pronóstico MA(2) | J14: Rechaza con 422 business-rule ("se requieren al menos 2 observaciones") y no guarda ejecución | K14: N/A | L14: No ejecutable: el servidor responde 501 Not Implemented (función pendiente de reglas de Industrial) | M14: BLOQUEADO
A15: CP-011 | B15: RF-11 | C15: =IF(B15="","",IFERROR(INDEX(Requisitos!$C$5:$C$60,MATCH(B15,Requisitos!$A$5:$A$60,0)),"¿Requisito no existe?")) | D15: Unitaria | E15: Valores límite | F15: Alta | G15: Serie C cargada | H15: Serie C: 0, 0, 0 | I15: Ejecutar MA(2) y calcular MAD y MAPE | J15: MAD = 0,00; MAPE sin valor, marcado "no calculable", 0 pares usados y 1 excluido | K15: N/A | L15: No ejecutable: el servidor responde 501 Not Implemented (función pendiente de reglas de Industrial) | M15: BLOQUEADO
A16: CP-012 | B16: RF-06 | C16: =IF(B16="","",IFERROR(INDEX(Requisitos!$C$5:$C$60,MATCH(B16,Requisitos!$A$5:$A$60,0)),"¿Requisito no existe?")) | D16: Integración | E16: Partición de equivalencia | F16: Alta | G16: Sesión como analista de datos | H16: Observación con valor −5 | I16: Cargar el lote | J16: 400 validation con el error junto al campo valor; el lote no se guarda | K16: N/A | L16: No ejecutable: el servidor responde 501 Not Implemented (función pendiente de reglas de Industrial) | M16: BLOQUEADO
A17: CP-013 | B17: RF-06 | C17: =IF(B17="","",IFERROR(INDEX(Requisitos!$C$5:$C$60,MATCH(B17,Requisitos!$A$5:$A$60,0)),"¿Requisito no existe?")) | D17: Integración | E17: Partición de equivalencia | F17: Alta | G17: Serie con el periodo 2026-01 cargado | H17: Segunda observación para 2026-01 | I17: Cargar el lote | J17: 409 conflict; la serie conserva una sola observación por periodo | K17: N/A | L17: No ejecutable: el servidor responde 501 Not Implemented (función pendiente de reglas de Industrial) | M17: BLOQUEADO
A18: CP-014 | B18: RF-06 | C18: =IF(B18="","",IFERROR(INDEX(Requisitos!$C$5:$C$60,MATCH(B18,Requisitos!$A$5:$A$60,0)),"¿Requisito no existe?")) | D18: Integración | E18: Valores límite | F18: Media | G18: Sesión como analista de datos | H18: Lote con el periodo 2026-03 sin valor | I18: Cargar el lote | J18: Rechaza el lote indicando el periodo; el dato ausente no se guarda como 0 | K18: N/A | L18: No ejecutable: el servidor responde 501 Not Implemented (función pendiente de reglas de Industrial) | M18: BLOQUEADO
A19: CP-015 | B19: RF-08 | C19: =IF(B19="","",IFERROR(INDEX(Requisitos!$C$5:$C$60,MATCH(B19,Requisitos!$A$5:$A$60,0)),"¿Requisito no existe?")) | D19: Integración | E19: Transición de estados | F19: Alta | G19: Ejecución MA(2) guardada sobre la serie A | H19: Corregir el periodo 2 de 120 a 125 | I19: Consultar la ejecución anterior | J19: Conserva las entradas originales (120), la ventana, el autor y la fecha; un fallo al guardar no deja resultados parciales | K19: N/A | L19: No ejecutable: el servidor responde 501 Not Implemented (función pendiente de reglas de Industrial) | M19: BLOQUEADO
A20: CP-016 | B20: RF-01 | C20: =IF(B20="","",IFERROR(INDEX(Requisitos!$C$5:$C$60,MATCH(B20,Requisitos!$A$5:$A$60,0)),"¿Requisito no existe?")) | D20: Integración | E20: Partición de equivalencia | F20: Alta | G20: Cuenta planeador activa | H20: Usuario planeador y clave válida | I20: GET /auth/csrf; POST /auth/login; GET /auth/me | J20: 200 con rol PLANNER y sus permisos; /me devuelve la misma sesión | K20: N/A | L20: 200, rol PLANNER y permisos del rol | M20: APROBADO | O20: Automatizado (mvnw test) + script API | P20: 22/10/2026
A21: CP-017 | B21: RF-01 | C21: =IF(B21="","",IFERROR(INDEX(Requisitos!$C$5:$C$60,MATCH(B21,Requisitos!$A$5:$A$60,0)),"¿Requisito no existe?")) | D21: Integración | E21: Partición de equivalencia | F21: Alta | G21: Ninguna | H21: Clave errónea; usuario inexistente | I21: POST /auth/login con cada combinación | J21: 401 invalid-credentials con el mismo mensaje en ambos casos | K21: N/A | L21: 401 y mensaje idéntico en ambos casos | M21: APROBADO | O21: Automatizado (mvnw test) + script API | P21: 22/10/2026
A22: CP-018 | B22: RF-01 | C22: =IF(B22="","",IFERROR(INDEX(Requisitos!$C$5:$C$60,MATCH(B22,Requisitos!$A$5:$A$60,0)),"¿Requisito no existe?")) | D22: Integración | E22: Transición de estados | F22: Alta | G22: Cuenta desactivada por el administrador | H22: Credenciales correctas de la cuenta inactiva | I22: POST /auth/login | J22: 401 con el mismo mensaje genérico | K22: N/A | L22: 401 con mensaje genérico | M22: APROBADO | O22: Automatizado (mvnw test) | P22: 22/10/2026
A23: CP-019 | B23: RF-01 | C23: =IF(B23="","",IFERROR(INDEX(Requisitos!$C$5:$C$60,MATCH(B23,Requisitos!$A$5:$A$60,0)),"¿Requisito no existe?")) | D23: Integración | E23: Transición de estados | F23: Alta | G23: Sesión iniciada | H23: Ninguno | I23: POST /auth/logout; GET /auth/me | J23: 204 y luego 401: la sesión queda invalidada | K23: N/A | L23: 204 y luego 401 | M23: APROBADO | O23: Automatizado (mvnw test) + script API | P23: 22/10/2026
A24: CP-020 | B24: RF-02 | C24: =IF(B24="","",IFERROR(INDEX(Requisitos!$C$5:$C$60,MATCH(B24,Requisitos!$A$5:$A$60,0)),"¿Requisito no existe?")) | D24: Integración | E24: Partición de equivalencia | F24: Alta | G24: Sesión como administrador | H24: Usuario nuevo, clave de 10 o más caracteres y un rol | I24: POST /admin/users; iniciar sesión con la cuenta nueva | J24: 201 con cabecera Location; la cuenta inicia sesión con el rol asignado | K24: N/A | L24: 201 y login con el rol asignado | M24: APROBADO | O24: Automatizado (mvnw test) | P24: 22/10/2026
A25: CP-021 | B25: RF-02 | C25: =IF(B25="","",IFERROR(INDEX(Requisitos!$C$5:$C$60,MATCH(B25,Requisitos!$A$5:$A$60,0)),"¿Requisito no existe?")) | D25: Integración | E25: Valores límite | F25: Alta | G25: Sesión como administrador | H25: Su propio id | I25: PATCH /admin/users/{id}/status y /role sobre sí mismo | J25: 422 business-rule; la cuenta sigue activa y con rol ADMIN | K25: N/A | L25: 422 en ambos casos; sin cambios | M25: APROBADO | O25: Automatizado (mvnw test) | P25: 22/10/2026
A26: CP-022 | B26: RF-02 | C26: =IF(B26="","",IFERROR(INDEX(Requisitos!$C$5:$C$60,MATCH(B26,Requisitos!$A$5:$A$60,0)),"¿Requisito no existe?")) | D26: Integración | E26: Transición de estados | F26: Alta | G26: Cuenta de analista con sesión abierta | H26: El administrador desactiva la cuenta | I26: Siguiente solicitud del analista | J26: 401: la sesión abierta termina | K26: N/A | L26: 401 en la siguiente solicitud | M26: APROBADO | O26: Automatizado (mvnw test) | P26: 22/10/2026
A27: CP-023 | B27: RF-03 | C27: =IF(B27="","",IFERROR(INDEX(Requisitos!$C$5:$C$60,MATCH(B27,Requisitos!$A$5:$A$60,0)),"¿Requisito no existe?")) | D27: Integración | E27: Tabla de decisión | F27: Alta | G27: Una sesión por cada rol | H27: 4 roles × 10 endpoints | I27: Invocar cada endpoint con cada rol | J27: Solo los roles de la matriz pasan (200 o 501 si la lógica está pendiente); el resto recibe 403 access-denied | K27: N/A | L27: 40 combinaciones conformes a la matriz | M27: APROBADO | O27: Automatizado (mvnw test) + script API | P27: 22/10/2026
A28: CP-024 | B28: RF-03 | C28: =IF(B28="","",IFERROR(INDEX(Requisitos!$C$5:$C$60,MATCH(B28,Requisitos!$A$5:$A$60,0)),"¿Requisito no existe?")) | D28: Integración | E28: Tabla de decisión | F28: Alta | G28: Sesión como administrador | H28: GET /history/products | I28: Consultar históricos con el administrador | J28: 403: el administrador no hereda permisos de negocio | K28: N/A | L28: 403 access-denied | M28: APROBADO | O28: Automatizado (mvnw test) + script API | P28: 22/10/2026
A29: CP-025 | B29: RF-03 | C29: =IF(B29="","",IFERROR(INDEX(Requisitos!$C$5:$C$60,MATCH(B29,Requisitos!$A$5:$A$60,0)),"¿Requisito no existe?")) | D29: Integración | E29: Tabla de decisión | F29: Alta | G29: Sesión como supervisor de línea | H29: POST /forecasts | I29: Intentar ejecutar un pronóstico | J29: 403 access-denied | K29: N/A | L29: 403 access-denied | M29: APROBADO | O29: Automatizado (mvnw test) + script API | P29: 22/10/2026
A30: CP-026 | B30: RF-04 | C30: =IF(B30="","",IFERROR(INDEX(Requisitos!$C$5:$C$60,MATCH(B30,Requisitos!$A$5:$A$60,0)),"¿Requisito no existe?")) | D30: Integración | E30: Basada en riesgo | F30: Media | G30: CP-017, CP-025 y CP-028 ejecutados | H30: Tabla evento | I30: Consultar los eventos registrados | J30: Hay LOGIN FAILURE, ACCESS_DENIED y CSRF_REJECTED; ninguna fila guarda contraseñas ni tokens | K30: N/A | L30: Eventos presentes; la tabla no tiene columnas de secretos | M30: APROBADO | O30: Automatizado (mvnw test) + script API | P30: 22/10/2026
A31: CP-027 | B31: RNF-01 | C31: =IF(B31="","",IFERROR(INDEX(Requisitos!$C$5:$C$60,MATCH(B31,Requisitos!$A$5:$A$60,0)),"¿Requisito no existe?")) | D31: Seguridad | E31: Tabla de decisión | F31: Alta | G31: Sin sesión | H31: 10 endpoints protegidos y una ruta sin versión | I31: Invocar cada uno sin cookie de sesión | J31: 401 authentication-required en todos | K31: N/A | L31: 401 en todos | M31: APROBADO | O31: Automatizado (mvnw test) + script API | P31: 22/10/2026
... A36: CP-032 | B36: RF-09 | C36: =IF(B36="","",IFERROR(INDEX(Requisitos!$C$5:$C$60,MATCH(B36,Requisitos!$A$5:$A$60,0)),"¿Requisito no existe?")) | D36: Integración | E36: Partición de equivalencia | F36: Media | G36: Ejecución de CP-001 guardada | H36: GET /forecasts y /forecasts/{id} | I36: Consultar la lista y el detalle | J36: Lista y detalle con método, ventana, autor, fecha, entradas y resultados | K36: N/A | L36: No ejecutable: el servidor responde 501 Not Implemented (función pendiente de reglas de Industrial) | M36: BLOQUEADO | O36: Script API | P36: 22/10/2026
A37: CP-033 | B37: RNF-03 | C37: =IF(B37="","",IFERROR(INDEX(Requisitos!$C$5:$C$60,MATCH(B37,Requisitos!$A$5:$A$60,0)),"¿Requisito no existe?")) | D37: Rendimiento | E37: Basada en riesgo | F37: Media | G37: Base con 1.000 observaciones | H37: 5 usuarios virtuales durante 5 minutos (k6) | I37: Consultar series y ejecutar pronósticos | J37: Percentil 95 ≤ 2 s, sin contar cargas de archivos | K37: N/A | L37: Programado para el corte 3 | M37: PENDIENTE
A38: CP-034 | B38: RNF-05 | C38: =IF(B38="","",IFERROR(INDEX(Requisitos!$C$5:$C$60,MATCH(B38,Requisitos!$A$5:$A$60,0)),"¿Requisito no existe?")) | D38: Usabilidad | E38: Exploratoria | F38: Media | G38: Frontend con históricos y pronóstico | H38: Tareas: consultar una serie y ejecutar un pronóstico | I38: Estudiantes de Industrial realizan las tareas | J38: Las completan sin ayuda; identifican producto, periodo y unidad y distinguen real de estimado | K38: N/A | L38: Programado para el corte 3 | M38: PENDIENTE
C39: =IF(B39="","",IFERROR(INDEX(Requisitos!$C$5:$C$60,MATCH(B39,Requisitos!$A$5:$A$60,0)),"¿Requisito no existe?"))
C40: =IF(B40="","",IFERROR(INDEX(Requisitos!$C$5:$C$60,MATCH(B40,Requisitos!$A$5:$A$60,0)),"¿Requisito no existe?"))
C41: =IF(B41="","",IFERROR(INDEX(Requisitos!$C$5:$C$60,MATCH(B41,Requisitos!$A$5:$A$60,0)),"¿Requisito no existe?"))
C42: =IF(B42="","",IFERROR(INDEX(Requisitos!$C$5:$C$60,MATCH(B42,Requisitos!$A$5:$A$60,0)),"¿Requisito no existe?"))
C43: =IF(B43="","",IFERROR(INDEX(Requisitos!$C$5:$C$60,MATCH(B43,Requisitos!$A$5:$A$60,0)),"¿Requisito no existe?"))
C44: =IF(B44="","",IFERROR(INDEX(Requisitos!$C$5:$C$60,MATCH(B44,Requisitos!$A$5:$A$60,0)),"¿Requisito no existe?"))
C45: =IF(B45="","",IFERROR(INDEX(Requisitos!$C$5:$C$60,MATCH(B45,Requisitos!$A$5:$A$60,0)),"¿Requisito no existe?"))
...

Sheet Verificacion
A1: Verificación numérica: sistema vs. cálculo de referencia
A2: Columna C = valor de Calculo_Referencia. Columna D = lo que devuelve el sistema (se escribe al ejecutar). El veredicto se calcula solo con la tolerancia de la columna F.
A4: ID caso | B4: Qué se verifica | C4: Valor de referencia (Excel) | D4: Valor del sistema | E4: Diferencia absoluta | F4: Tolerancia | G4: Unidad | H4: Veredicto | I4: Defecto asociado
A5: CP-001 | B5: MA(2) serie A · pronóstico periodo 3 | C5: =Calculo_Referencia!C7 | E5: =IF(OR(C5="",D5=""),"",ABS(D5-C5)) | F5: 0.01 | G5: unidades | H5: =IF(C5="","",IF(D5="","PENDIENTE",IF(ABS(D5-C5)<=F5,"APROBADO","FALLIDO")))
A6: CP-002 | B6: MA(2) serie A · pronóstico periodo 4 | C6: =Calculo_Referencia!C8 | E6: =IF(OR(C6="",D6=""),"",ABS(D6-C6)) | F6: 0.01 | G6: unidades | H6: =IF(C6="","",IF(D6="","PENDIENTE",IF(ABS(D6-C6)<=F6,"APROBADO","FALLIDO")))
A7: CP-003 | B7: MA(2) serie A · estimación periodo 5 | C7: =Calculo_Referencia!C9 | E7: =IF(OR(C7="",D7=""),"",ABS(D7-C7)) | F7: 0.01 | G7: unidades | H7: =IF(C7="","",IF(D7="","PENDIENTE",IF(ABS(D7-C7)<=F7,"APROBADO","FALLIDO")))
A8: CP-004 | B8: Serie A · MAD | C8: =Calculo_Referencia!R10 | E8: =IF(OR(C8="",D8=""),"",ABS(D8-C8)) | F8: 0.01 | G8: unidades | H8: =IF(C8="","",IF(D8="","PENDIENTE",IF(ABS(D8-C8)<=F8,"APROBADO","FALLIDO")))
A9: CP-005 | B9: Serie A · MAPE | C9: =Calculo_Referencia!R11 | E9: =IF(OR(C9="",D9=""),"",ABS(D9-C9)) | F9: 0.01 | G9: % (puntos) | H9: =IF(C9="","",IF(D9="","PENDIENTE",IF(ABS(D9-C9)<=F9,"APROBADO","FALLIDO")))
A10: CP-006 | B10: MA(2) serie B · pronóstico periodo 4 | C10: =Calculo_Referencia!K8 | E10: =IF(OR(C10="",D10=""),"",ABS(D10-C10)) | F10: 0.01 | G10: unidades | H10: =IF(C10="","",IF(D10="","PENDIENTE",IF(ABS(D10-C10)<=F10,"APROBADO","FALLIDO")))
A11: CP-007 | B11: Serie B · MAD | C11: =Calculo_Referencia!R14 | E11: =IF(OR(C11="",D11=""),"",ABS(D11-C11)) | F11: 0.01 | G11: unidades | H11: =IF(C11="","",IF(D11="","PENDIENTE",IF(ABS(D11-C11)<=F11,"APROBADO","FALLIDO")))
A12: CP-008 | B12: Serie B · MAPE (excluye el real = 0) | C12: =Calculo_Referencia!R15 | E12: =IF(OR(C12="",D12=""),"",ABS(D12-C12)) | F12: 0.01 | G12: % (puntos) | H12: =IF(C12="","",IF(D12="","PENDIENTE",IF(ABS(D12-C12)<=F12,"APROBADO","FALLIDO")))
A13: CP-009 | B13: MA(2) serie B · estimación periodo 6 | C13: =Calculo_Referencia!K10 | E13: =IF(OR(C13="",D13=""),"",ABS(D13-C13)) | F13: 0.01 | G13: unidades | H13: =IF(C13="","",IF(D13="","PENDIENTE",IF(ABS(D13-C13)<=F13,"APROBADO","FALLIDO")))
E14: =IF(OR(C14="",D14=""),"",ABS(D14-C14)) | H14: =IF(C14="","",IF(D14="","PENDIENTE",IF(ABS(D14-C14)<=F14,"APROBADO","FALLIDO")))
E15: =IF(OR(C15="",D15=""),"",ABS(D15-C15)) | H15: =IF(C15="","",IF(D15="","PENDIENTE",IF(ABS(D15-C15)<=F15,"APROBADO","FALLIDO")))
E16: =IF(OR(C16="",D16=""),"",ABS(D16-C16)) | H16: =IF(C16="","",IF(D16="","PENDIENTE",IF(ABS(D16-C16)<=F16,"APROBADO","FALLIDO")))
E17: =IF(OR(C17="",D17=""),"",ABS(D17-C17)) | H17: =IF(C17="","",IF(D17="","PENDIENTE",IF(ABS(D17-C17)<=F17,"APROBADO","FALLIDO")))
E18: =IF(OR(C18="",D18=""),"",ABS(D18-C18)) | H18: =IF(C18="","",IF(D18="","PENDIENTE",IF(ABS(D18-C18)<=F18,"APROBADO","FALLIDO")))
E19: =IF(OR(C19="",D19=""),"",ABS(D19-C19)) | H19: =IF(C19="","",IF(D19="","PENDIENTE",IF(ABS(D19-C19)<=F19,"APROBADO","FALLIDO")))
E20: =IF(OR(C20="",D20=""),"",ABS(D20-C20)) | H20: =IF(C20="","",IF(D20="","PENDIENTE",IF(ABS(D20-C20)<=F20,"APROBADO","FALLIDO")))
E21: =IF(OR(C21="",D21=""),"",ABS(D21-C21)) | H21: =IF(C21="","",IF(D21="","PENDIENTE",IF(ABS(D21-C21)<=F21,"APROBADO","FALLIDO")))
E22: =IF(OR(C22="",D22=""),"",ABS(D22-C22)) | H22: =IF(C22="","",IF(D22="","PENDIENTE",IF(ABS(D22-C22)<=F22,"APROBADO","FALLIDO")))
E23: =IF(OR(C23="",D23=""),"",ABS(D23-C23)) | H23: =IF(C23="","",IF(D23="","PENDIENTE",IF(ABS(D23-C23)<=F23,"APROBADO","FALLIDO")))
E24: =IF(OR(C24="",D24=""),"",ABS(D24-C24)) | H24: =IF(C24="","",IF(D24="","PENDIENTE",IF(ABS(D24-C24)<=F24,"APROBADO","FALLIDO")))
A26: Estado al 22/10/2026: POST /api/v1/forecasts responde 501 Not Implemented, así que la columna D sigue vacía y los nueve casos figuran como PENDIENTE. Al implementarse el cálculo se escribe el valor devuelto (sin redondear) y el veredicto aparece solo.
A27: Tolerancia 0,01 = diferencia máxima aceptada (unidades para pronóstico y MAD; puntos porcentuales para MAPE). Propuesta en la arquitectura; se firma con Industrial en el Anexo B del plan maestro.

Sheet Matriz
A1: Matriz de trazabilidad requisitos–pruebas (E1.2)
A2: Se alimenta de Requisitos y Catalogo. Se completan a mano: Casos de prueba (lista), Nivel / herramienta y Defectos. El N.º de casos, la cobertura y el estado se calculan.
A4: ID requisito | B4: Descripción | C4: Módulo | D4: Tipo | E4: Prioridad | F4: Casos de prueba (lista) | G4: N.º casos (auto) | H4: Cobertura (auto) | I4: Nivel / herramienta | J4: Estado (auto) | K4: Defectos asociados
A5: =IF(Requisitos!A5="","",Requisitos!A5) | B5: =IF($A5="","",Requisitos!B5) | C5: =IF($A5="","",Requisitos!C5) | D5: =IF($A5="","",Requisitos!D5) | E5: =IF($A5="","",Requisitos!E5) | F5: CP-016, CP-017, CP-018, CP-019 | G5: =IF($A5="","",COUNTIF(Catalogo!$B$5:$B$104,$A5)) | H5: =IF($A5="","",IF(G5=0,"SIN COBERTURA","Cubierto")) | I5: Integración / MockMvc + script API | J5: =IF($A5="","",IF(G5=0,"Sin casos",IF(COUNTIFS(Catalogo!$B$5:$B$104,$A5,Catalogo!$M$5:$M$104,"FALLIDO")>0,"Fallido",IF(COUNTIFS(Catalogo!$B$5:$B$104,$A5,Catalogo!$M$5:$M$104,"APROBADO")=G5,"Aprobado","Pendiente"))))
A6: =IF(Requisitos!A6="","",Requisitos!A6) | B6: =IF($A6="","",Requisitos!B6) | C6: =IF($A6="","",Requisitos!C6) | D6: =IF($A6="","",Requisitos!D6) | E6: =IF($A6="","",Requisitos!E6) | F6: CP-020, CP-021, CP-022 | G6: =IF($A6="","",COUNTIF(Catalogo!$B$5:$B$104,$A6)) | H6: =IF($A6="","",IF(G6=0,"SIN COBERTURA","Cubierto")) | I6: Integración / MockMvc | J6: =IF($A6="","",IF(G6=0,"Sin casos",IF(COUNTIFS(Catalogo!$B$5:$B$104,$A6,Catalogo!$M$5:$M$104,"FALLIDO")>0,"Fallido",IF(COUNTIFS(Catalogo!$B$5:$B$104,$A6,Catalogo!$M$5:$M$104,"APROBADO")=G6,"Aprobado","Pendiente"))))
A7: =IF(Requisitos!A7="","",Requisitos!A7) | B7: =IF($A7="","",Requisitos!B7) | C7: =IF($A7="","",Requisitos!C7) | D7: =IF($A7="","",Requisitos!D7) | E7: =IF($A7="","",Requisitos!E7) | F7: CP-023, CP-024, CP-025 | G7: =IF($A7="","",COUNTIF(Catalogo!$B$5:$B$104,$A7)) | H7: =IF($A7="","",IF(G7=0,"SIN COBERTURA","Cubierto")) | I7: Integración / MockMvc + script API | J7: =IF($A7="","",IF(G7=0,"Sin casos",IF(COUNTIFS(Catalogo!$B$5:$B$104,$A7,Catalogo!$M$5:$M$104,"FALLIDO")>0,"Fallido",IF(COUNTIFS(Catalogo!$B$5:$B$104,$A7,Catalogo!$M$5:$M$104,"APROBADO")=G7,"Aprobado","Pendiente"))))
A8: =IF(Requisitos!A8="","",Requisitos!A8) | B8: =IF($A8="","",Requisitos!B8) | C8: =IF($A8="","",Requisitos!C8) | D8: =IF($A8="","",Requisitos!D8) | E8: =IF($A8="","",Requisitos!E8) | F8: CP-026 | G8: =IF($A8="","",COUNTIF(Catalogo!$B$5:$B$104,$A8)) | H8: =IF($A8="","",IF(G8=0,"SIN COBERTURA","Cubierto")) | I8: Integración / MockMvc + consulta SQL | J8: =IF($A8="","",IF(G8=0,"Sin casos",IF(COUNTIFS(Catalogo!$B$5:$B$104,$A8,Catalogo!$M$5:$M$104,"FALLIDO")>0,"Fallido",IF(COUNTIFS(Catalogo!$B$5:$B$104,$A8,Catalogo!$M$5:$M$104,"APROBADO")=G8,"Aprobado","Pendiente"))))
A9: =IF(Requisitos!A9="","",Requisitos!A9) | B9: =IF($A9="","",Requisitos!B9) | C9: =IF($A9="","",Requisitos!C9) | D9: =IF($A9="","",Requisitos!D9) | E9: =IF($A9="","",Requisitos!E9) | F9: CP-031 | G9: =IF($A9="","",COUNTIF(Catalogo!$B$5:$B$104,$A9)) | H9: =IF($A9="","",IF(G9=0,"SIN COBERTURA","Cubierto")) | I9: Integración / MockMvc + script API | J9: =IF($A9="","",IF(G9=0,"Sin casos",IF(COUNTIFS(Catalogo!$B$5:$B$104,$A9,Catalogo!$M$5:$M$104,"FALLIDO")>0,"Fallido",IF(COUNTIFS(Catalogo!$B$5:$B$104,$A9,Catalogo!$M$5:$M$104,"APROBADO")=G9,"Aprobado","Pendiente"))))
A10: =IF(Requisitos!A10="","",Requisitos!A10) | B10: =IF($A10="","",Requisitos!B10) | C10: =IF($A10="","",Requisitos!C10) | D10: =IF($A10="","",Requisitos!D10) | E10: =IF($A10="","",Requisitos!E10) | F10: CP-012, CP-013, CP-014 | G10: =IF($A10="","",COUNTIF(Catalogo!$B$5:$B$104,$A10)) | H10: =IF($A10="","",IF(G10=0,"SIN COBERTURA","Cubierto")) | I10: Integración / MockMvc | J10: =IF($A10="","",IF(G10=0,"Sin casos",IF(COUNTIFS(Catalogo!$B$5:$B$104,$A10,Catalogo!$M$5:$M$104,"FALLIDO")>0,"Fallido",IF(COUNTIFS(Catalogo!$B$5:$B$104,$A10,Catalogo!$M$5:$M$104,"APROBADO")=G10,"Aprobado","Pendiente"))))
A11: =IF(Requisitos!A11="","",Requisitos!A11) | B11: =IF($A11="","",Requisitos!B11) | C11: =IF($A11="","",Requisitos!C11) | D11: =IF($A11="","",Requisitos!D11) | E11: =IF($A11="","",Requisitos!E11) | F11: CP-001, CP-002, CP-003, CP-006, CP-009, CP-010 | G11: =IF($A11="","",COUNTIF(Catalogo!$B$5:$B$104,$A11)) | H11: =IF($A11="","",IF(G11=0,"SIN COBERTURA","Cubierto")) | I11: Unitaria / JUnit 5 | J11: =IF($A11="","",IF(G11=0,"Sin casos",IF(COUNTIFS(Catalogo!$B$5:$B$104,$A11,Catalogo!$M$5:$M$104,"FALLIDO")>0,"Fallido",IF(COUNTIFS(Catalogo!$B$5:$B$104,$A11,Catalogo!$M$5:$M$104,"APROBADO")=G11,"Aprobado","Pendiente"))))
A12: =IF(Requisitos!A12="","",Requisitos!A12) | B12: =IF($A12="","",Requisitos!B12) | C12: =IF($A12="","",Requisitos!C12) | D12: =IF($A12="","",Requisitos!D12) | E12: =IF($A12="","",Requisitos!E12) | F12: CP-015 | G12: =IF($A12="","",COUNTIF(Catalogo!$B$5:$B$104,$A12)) | H12: =IF($A12="","",IF(G12=0,"SIN COBERTURA","Cubierto")) | I12: Integración / MockMvc | J12: =IF($A12="","",IF(G12=0,"Sin casos",IF(COUNTIFS(Catalogo!$B$5:$B$104,$A12,Catalogo!$M$5:$M$104,"FALLIDO")>0,"Fallido",IF(COUNTIFS(Catalogo!$B$5:$B$104,$A12,Catalogo!$M$5:$M$104,"APROBADO")=G12,"Aprobado","Pendiente"))))
A13: =IF(Requisitos!A13="","",Requisitos!A13) | B13: =IF($A13="","",Requisitos!B13) | C13: =IF($A13="","",Requisitos!C13) | D13: =IF($A13="","",Requisitos!D13) | E13: =IF($A13="","",Requisitos!E13) | F13: CP-032 | G13: =IF($A13="","",COUNTIF(Catalogo!$B$5:$B$104,$A13)) | H13: =IF($A13="","",IF(G13=0,"SIN COBERTURA","Cubierto")) | I13: Integración / MockMvc + script API | J13: =IF($A13="","",IF(G13=0,"Sin casos",IF(COUNTIFS(Catalogo!$B$5:$B$104,$A13,Catalogo!$M$5:$M$104,"FALLIDO")>0,"Fallido",IF(COUNTIFS(Catalogo!$B$5:$B$104,$A13,Catalogo!$M$5:$M$104,"APROBADO")=G13,"Aprobado","Pendiente"))))
A14: =IF(Requisitos!A14="","",Requisitos!A14) | B14: =IF($A14="","",Requisitos!B14) | C14: =IF($A14="","",Requisitos!C14) | D14: =IF($A14="","",Requisitos!D14) | E14: =IF($A14="","",Requisitos!E14) | F14: CP-004, CP-007 | G14: =IF($A14="","",COUNTIF(Catalogo!$B$5:$B$104,$A14)) | H14: =IF($A14="","",IF(G14=0,"SIN COBERTURA","Cubierto")) | I14: Unitaria / JUnit 5 | J14: =IF($A14="","",IF(G14=0,"Sin casos",IF(COUNTIFS(Catalogo!$B$5:$B$104,$A14,Catalogo!$M$5:$M$104,"FALLIDO")>0,"Fallido",IF(COUNTIFS(Catalogo!$B$5:$B$104,$A14,Catalogo!$M$5:$M$104,"APROBADO")=G14,"Aprobado","Pendiente"))))
A15: =IF(Requisitos!A15="","",Requisitos!A15) | B15: =IF($A15="","",Requisitos!B15) | C15: =IF($A15="","",Requisitos!C15) | D15: =IF($A15="","",Requisitos!D15) | E15: =IF($A15="","",Requisitos!E15) | F15: CP-005, CP-008, CP-011 | G15: =IF($A15="","",COUNTIF(Catalogo!$B$5:$B$104,$A15)) | H15: =IF($A15="","",IF(G15=0,"SIN COBERTURA","Cubierto")) | I15: Unitaria / JUnit 5 | J15: =IF($A15="","",IF(G15=0,"Sin casos",IF(COUNTIFS(Catalogo!$B$5:$B$104,$A15,Catalogo!$M$5:$M$104,"FALLIDO")>0,"Fallido",IF(COUNTIFS(Catalogo!$B$5:$B$104,$A15,Catalogo!$M$5:$M$104,"APROBADO")=G15,"Aprobado","Pendiente"))))
A16: =IF(Requisitos!A16="","",Requisitos!A16) | B16: =IF($A16="","",Requisitos!B16) | C16: =IF($A16="","",Requisitos!C16) | D16: =IF($A16="","",Requisitos!D16) | E16: =IF($A16="","",Requisitos!E16) | F16: CP-027, CP-028 | G16: =IF($A16="","",COUNTIF(Catalogo!$B$5:$B$104,$A16)) | H16: =IF($A16="","",IF(G16=0,"SIN COBERTURA","Cubierto")) | I16: Seguridad / MockMvc + script API | J16: =IF($A16="","",IF(G16=0,"Sin casos",IF(COUNTIFS(Catalogo!$B$5:$B$104,$A16,Catalogo!$M$5:$M$104,"FALLIDO")>0,"Fallido",IF(COUNTIFS(Catalogo!$B$5:$B$104,$A16,Catalogo!$M$5:$M$104,"APROBADO")=G16,"Aprobado","Pendiente"))))
... A20: =IF(Requisitos!A20="","",Requisitos!A20) | B20: =IF($A20="","",Requisitos!B20) | C20: =IF($A20="","",Requisitos!C20) | D20: =IF($A20="","",Requisitos!D20) | E20: =IF($A20="","",Requisitos!E20) | F20: CP-034 | G20: =IF($A20="","",COUNTIF(Catalogo!$B$5:$B$104,$A20)) | H20: =IF($A20="","",IF(G20=0,"SIN COBERTURA","Cubierto")) | I20: Usabilidad / sesión con Industrial | J20: =IF($A20="","",IF(G20=0,"Sin casos",IF(COUNTIFS(Catalogo!$B$5:$B$104,$A20,Catalogo!$M$5:$M$104,"FALLIDO")>0,"Fallido",IF(COUNTIFS(Catalogo!$B$5:$B$104,$A20,Catalogo!$M$5:$M$104,"APROBADO")=G20,"Aprobado","Pendiente"))))
A21: =IF(Requisitos!A21="","",Requisitos!A21) | B21: =IF($A21="","",Requisitos!B21) | C21: =IF($A21="","",Requisitos!C21) | D21: =IF($A21="","",Requisitos!D21) | E21: =IF($A21="","",Requisitos!E21) | G21: =IF($A21="","",COUNTIF(Catalogo!$B$5:$B$104,$A21)) | H21: =IF($A21="","",IF(G21=0,"SIN COBERTURA","Cubierto")) | J21: =IF($A21="","",IF(G21=0,"Sin casos",IF(COUNTIFS(Catalogo!$B$5:$B$104,$A21,Catalogo!$M$5:$M$104,"FALLIDO")>0,"Fallido",IF(COUNTIFS(Catalogo!$B$5:$B$104,$A21,Catalogo!$M$5:$M$104,"APROBADO")=G21,"Aprobado","Pendiente"))))
A22: =IF(Requisitos!A22="","",Requisitos!A22) | B22: =IF($A22="","",Requisitos!B22) | C22: =IF($A22="","",Requisitos!C22) | D22: =IF($A22="","",Requisitos!D22) | E22: =IF($A22="","",Requisitos!E22) | G22: =IF($A22="","",COUNTIF(Catalogo!$B$5:$B$104,$A22)) | H22: =IF($A22="","",IF(G22=0,"SIN COBERTURA","Cubierto")) | J22: =IF($A22="","",IF(G22=0,"Sin casos",IF(COUNTIFS(Catalogo!$B$5:$B$104,$A22,Catalogo!$M$5:$M$104,"FALLIDO")>0,"Fallido",IF(COUNTIFS(Catalogo!$B$5:$B$104,$A22,Catalogo!$M$5:$M$104,"APROBADO")=G22,"Aprobado","Pendiente"))))
A23: =IF(Requisitos!A23="","",Requisitos!A23) | B23: =IF($A23="","",Requisitos!B23) | C23: =IF($A23="","",Requisitos!C23) | D23: =IF($A23="","",Requisitos!D23) | E23: =IF($A23="","",Requisitos!E23) | G23: =IF($A23="","",COUNTIF(Catalogo!$B$5:$B$104,$A23)) | H23: =IF($A23="","",IF(G23=0,"SIN COBERTURA","Cubierto")) | J23: =IF($A23="","",IF(G23=0,"Sin casos",IF(COUNTIFS(Catalogo!$B$5:$B$104,$A23,Catalogo!$M$5:$M$104,"FALLIDO")>0,"Fallido",IF(COUNTIFS(Catalogo!$B$5:$B$104,$A23,Catalogo!$M$5:$M$104,"APROBADO")=G23,"Aprobado","Pendiente"))))
A24: =IF(Requisitos!A24="","",Requisitos!A24) | B24: =IF($A24="","",Requisitos!B24) | C24: =IF($A24="","",Requisitos!C24) | D24: =IF($A24="","",Requisitos!D24) | E24: =IF($A24="","",Requisitos!E24) | G24: =IF($A24="","",COUNTIF(Catalogo!$B$5:$B$104,$A24)) | H24: =IF($A24="","",IF(G24=0,"SIN COBERTURA","Cubierto")) | J24: =IF($A24="","",IF(G24=0,"Sin casos",IF(COUNTIFS(Catalogo!$B$5:$B$104,$A24,Catalogo!$M$5:$M$104,"FALLIDO")>0,"Fallido",IF(COUNTIFS(Catalogo!$B$5:$B$104,$A24,Catalogo!$M$5:$M$104,"APROBADO")=G24,"Aprobado","Pendiente"))))
A25: =IF(Requisitos!A25="","",Requisitos!A25) | B25: =IF($A25="","",Requisitos!B25) | C25: =IF($A25="","",Requisitos!C25) | D25: =IF($A25="","",Requisitos!D25) | E25: =IF($A25="","",Requisitos!E25) | G25: =IF($A25="","",COUNTIF(Catalogo!$B$5:$B$104,$A25)) | H25: =IF($A25="","",IF(G25=0,"SIN COBERTURA","Cubierto")) | J25: =IF($A25="","",IF(G25=0,"Sin casos",IF(COUNTIFS(Catalogo!$B$5:$B$104,$A25,Catalogo!$M$5:$M$104,"FALLIDO")>0,"Fallido",IF(COUNTIFS(Catalogo!$B$5:$B$104,$A25,Catalogo!$M$5:$M$104,"APROBADO")=G25,"Aprobado","Pendiente"))))
A26: =IF(Requisitos!A26="","",Requisitos!A26) | B26: =IF($A26="","",Requisitos!B26) | C26: =IF($A26="","",Requisitos!C26) | D26: =IF($A26="","",Requisitos!D26) | E26: =IF($A26="","",Requisitos!E26) | G26: =IF($A26="","",COUNTIF(Catalogo!$B$5:$B$104,$A26)) | H26: =IF($A26="","",IF(G26=0,"SIN COBERTURA","Cubierto")) | J26: =IF($A26="","",IF(G26=0,"Sin casos",IF(COUNTIFS(Catalogo!$B$5:$B$104,$A26,Catalogo!$M$5:$M$104,"FALLIDO")>0,"Fallido",IF(COUNTIFS(Catalogo!$B$5:$B$104,$A26,Catalogo!$M$5:$M$104,"APROBADO")=G26,"Aprobado","Pendiente"))))
A27: =IF(Requisitos!A27="","",Requisitos!A27) | B27: =IF($A27="","",Requisitos!B27) | C27: =IF($A27="","",Requisitos!C27) | D27: =IF($A27="","",Requisitos!D27) | E27: =IF($A27="","",Requisitos!E27) | G27: =IF($A27="","",COUNTIF(Catalogo!$B$5:$B$104,$A27)) | H27: =IF($A27="","",IF(G27=0,"SIN COBERTURA","Cubierto")) | J27: =IF($A27="","",IF(G27=0,"Sin casos",IF(COUNTIFS(Catalogo!$B$5:$B$104,$A27,Catalogo!$M$5:$M$104,"FALLIDO")>0,"Fallido",IF(COUNTIFS(Catalogo!$B$5:$B$104,$A27,Catalogo!$M$5:$M$104,"APROBADO")=G27,"Aprobado","Pendiente"))))
A28: =IF(Requisitos!A28="","",Requisitos!A28) | B28: =IF($A28="","",Requisitos!B28) | C28: =IF($A28="","",Requisitos!C28) | D28: =IF($A28="","",Requisitos!D28) | E28: =IF($A28="","",Requisitos!E28) | G28: =IF($A28="","",COUNTIF(Catalogo!$B$5:$B$104,$A28)) | H28: =IF($A28="","",IF(G28=0,"SIN COBERTURA","Cubierto")) | J28: =IF($A28="","",IF(G28=0,"Sin casos",IF(COUNTIFS(Catalogo!$B$5:$B$104,$A28,Catalogo!$M$5:$M$104,"FALLIDO")>0,"Fallido",IF(COUNTIFS(Catalogo!$B$5:$B$104,$A28,Catalogo!$M$5:$M$104,"APROBADO")=G28,"Aprobado","Pendiente"))))
A29: =IF(Requisitos!A29="","",Requisitos!A29) | B29: =IF($A29="","",Requisitos!B29) | C29: =IF($A29="","",Requisitos!C29) | D29: =IF($A29="","",Requisitos!D29) | E29: =IF($A29="","",Requisitos!E29) | G29: =IF($A29="","",COUNTIF(Catalogo!$B$5:$B$104,$A29)) | H29: =IF($A29="","",IF(G29=0,"SIN COBERTURA","Cubierto")) | J29: =IF($A29="","",IF(G29=0,"Sin casos",IF(COUNTIFS(Catalogo!$B$5:$B$104,$A29,Catalogo!$M$5:$M$104,"FALLIDO")>0,"Fallido",IF(COUNTIFS(Catalogo!$B$5:$B$104,$A29,Catalogo!$M$5:$M$104,"APROBADO")=G29,"Aprobado","Pendiente"))))
A30: =IF(Requisitos!A30="","",Requisitos!A30) | B30: =IF($A30="","",Requisitos!B30) | C30: =IF($A30="","",Requisitos!C30) | D30: =IF($A30="","",Requisitos!D30) | E30: =IF($A30="","",Requisitos!E30) | G30: =IF($A30="","",COUNTIF(Catalogo!$B$5:$B$104,$A30)) | H30: =IF($A30="","",IF(G30=0,"SIN COBERTURA","Cubierto")) | J30: =IF($A30="","",IF(G30=0,"Sin casos",IF(COUNTIFS(Catalogo!$B$5:$B$104,$A30,Catalogo!$M$5:$M$104,"FALLIDO")>0,"Fallido",IF(COUNTIFS(Catalogo!$B$5:$B$104,$A30,Catalogo!$M$5:$M$104,"APROBADO")=G30,"Aprobado","Pendiente"))))
A31: =IF(Requisitos!A31="","",Requisitos!A31) | B31: =IF($A31="","",Requisitos!B31) | C31: =IF($A31="","",Requisitos!C31) | D31: =IF($A31="","",Requisitos!D31) | E31: =IF($A31="","",Requisitos!E31) | G31: =IF($A31="","",COUNTIF(Catalogo!$B$5:$B$104,$A31)) | H31: =IF($A31="","",IF(G31=0,"SIN COBERTURA","Cubierto")) | J31: =IF($A31="","",IF(G31=0,"Sin casos",IF(COUNTIFS(Catalogo!$B$5:$B$104,$A31,Catalogo!$M$5:$M$104,"FALLIDO")>0,"Fallido",IF(COUNTIFS(Catalogo!$B$5:$B$104,$A31,Catalogo!$M$5:$M$104,"APROBADO")=G31,"Aprobado","Pendiente"))))
A32: =IF(Requisitos!A32="","",Requisitos!A32) | B32: =IF($A32="","",Requisitos!B32) | C32: =IF($A32="","",Requisitos!C32) | D32: =IF($A32="","",Requisitos!D32) | E32: =IF($A32="","",Requisitos!E32) | G32: =IF($A32="","",COUNTIF(Catalogo!$B$5:$B$104,$A32)) | H32: =IF($A32="","",IF(G32=0,"SIN COBERTURA","Cubierto")) | J32: =IF($A32="","",IF(G32=0,"Sin casos",IF(COUNTIFS(Catalogo!$B$5:$B$104,$A32,Catalogo!$M$5:$M$104,"FALLIDO")>0,"Fallido",IF(COUNTIFS(Catalogo!$B$5:$B$104,$A32,Catalogo!$M$5:$M$104,"APROBADO")=G32,"Aprobado","Pendiente"))))
... A60: =IF(Requisitos!A60="","",Requisitos!A60) | B60: =IF($A60="","",Requisitos!B60) | C60: =IF($A60="","",Requisitos!C60) | D60: =IF($A60="","",Requisitos!D60) | E60: =IF($A60="","",Requisitos!E60) | G60: =IF($A60="","",COUNTIF(Catalogo!$B$5:$B$104,$A60)) | H60: =IF($A60="","",IF(G60=0,"SIN COBERTURA","Cubierto")) | J60: =IF($A60="","",IF(G60=0,"Sin casos",IF(COUNTIFS(Catalogo!$B$5:$B$104,$A60,Catalogo!$M$5:$M$104,"FALLIDO")>0,"Fallido",IF(COUNTIFS(Catalogo!$B$5:$B$104,$A60,Catalogo!$M$5:$M$104,"APROBADO")=G60,"Aprobado","Pendiente"))))
A62: Los 16 requisitos tienen al menos un caso. "Pendiente" en Estado significa que el requisito tiene casos BLOQUEADOS o sin ejecutar; ninguno ha fallado.

Sheet Cobertura
A1: Resumen de cobertura (se calcula solo)
A2: No escribas aquí. Sirve para revisar tu entrega antes de enviarla.
A4: Indicador | B4: Valor
A5: Total de requisitos | B5: =COUNTA(Requisitos!A5:A60)
A6: Requisitos con al menos un caso | B6: =COUNTIF(Matriz!G5:G60,">0")
A7: % de requisitos cubiertos | B7: =IF(B5=0,0,B6/B5)
A8: Requisitos sin cobertura | B8: =B5-B6
A9: Casos de prueba totales | B9: =COUNTA(Catalogo!A5:A104)
A10: Casos de verificación numérica | B10: =COUNTIF(Catalogo!E5:E104,"Verificación numérica")
A11: Casos "huérfanos" (requisito inexistente) | B11: =SUMPRODUCT((Catalogo!B5:B104<>"")*(COUNTIF(Requisitos!A5:A60,Catalogo!B5:B104)=0))
A12: ¿Mínimo 20 casos? | B12: =IF(B9>=20,"CUMPLE","FALTAN "&(20-B9))
A13: ¿Mínimo 8 casos de verificación numérica? | B13: =IF(B10>=8,"CUMPLE","FALTAN "&(8-B10))
A14: ¿100 % de requisitos con caso de prueba? | B14: =IF(B5=0,"SIN DATOS",IF(B8=0,"CUMPLE","FALTAN "&B8&" REQUISITO(S)"))
A17: Módulo | B17: Requisitos | C17: Con caso | D17: % cubierto
A18: Autenticación y roles | B18: =COUNTIF(Requisitos!$C$5:$C$60,A18) | C18: =COUNTIFS(Matriz!$C$5:$C$60,A18,Matriz!$G$5:$G$60,">0") | D18: =IF(B18=0,"",C18/B18)
A19: Históricos | B19: =COUNTIF(Requisitos!$C$5:$C$60,A19) | C19: =COUNTIFS(Matriz!$C$5:$C$60,A19,Matriz!$G$5:$G$60,">0") | D19: =IF(B19=0,"",C19/B19)
A20: Pronóstico | B20: =COUNTIF(Requisitos!$C$5:$C$60,A20) | C20: =COUNTIFS(Matriz!$C$5:$C$60,A20,Matriz!$G$5:$G$60,">0") | D20: =IF(B20=0,"",C20/B20)
A21: Indicadores | B21: =COUNTIF(Requisitos!$C$5:$C$60,A21) | C21: =COUNTIFS(Matriz!$C$5:$C$60,A21,Matriz!$G$5:$G$60,">0") | D21: =IF(B21=0,"",C21/B21)
A22: Transversal | B22: =COUNTIF(Requisitos!$C$5:$C$60,A22) | C22: =COUNTIFS(Matriz!$C$5:$C$60,A22,Matriz!$G$5:$G$60,">0") | D22: =IF(B22=0,"",C22/B22)
A25: Veredicto de los casos | B25: Cantidad
A26: PENDIENTE | B26: =COUNTIF(Catalogo!$M$5:$M$104,A26)
A27: APROBADO | B27: =COUNTIF(Catalogo!$M$5:$M$104,A27)
A28: FALLIDO | B28: =COUNTIF(Catalogo!$M$5:$M$104,A28)
A29: BLOQUEADO | B29: =COUNTIF(Catalogo!$M$5:$M$104,A29)

Sheet Riesgos
A1: Matriz de riesgos (sección 7 del plan maestro)
A2: Exposición = probabilidad × impacto (escala 1 a 5). Nivel: Alto ≥ 15 · Medio 8–14 · Bajo < 8. Las pruebas se priorizan por el nivel de riesgo.
A4: ID | B4: Riesgo | C4: Módulo | D4: Tipo | E4: Probabilidad (1-5) | F4: Impacto (1-5) | G4: Exposición | H4: Nivel | I4: Estrategia de prueba / mitigación | J4: Casos relacionados | K4: Estado
A5: R-01 | B5: MAPE mal calculado cuando el valor real es 0 (división por cero o pares mal excluidos) | C5: Indicadores | D5: Producto | E5: 4 | F5: 5 | G5: =IF(OR(E5="",F5=""),"",E5*F5) | H5: =IF(G5="","",IF(G5>=15,"Alto",IF(G5>=8,"Medio","Bajo"))) | I5: Valores límite y verificación numérica contra Calculo_Referencia | J5: CP-005, CP-008, CP-011 | K5: Abierto
A6: R-02 | B6: El promedio móvil usa el dato del periodo que pronostica o redondea antes de tiempo | C6: Pronóstico | D6: Producto | E6: 3 | F6: 5 | G6: =IF(OR(E6="",F6=""),"",E6*F6) | H6: =IF(G6="","",IF(G6>=15,"Alto",IF(G6>=8,"Medio","Bajo"))) | I6: Verificación numérica con tolerancia 0,01 sobre dos series | J6: CP-001 a CP-009 | K6: Abierto
A7: R-03 | B7: Acceso indebido por rol (por ejemplo, el administrador modifica históricos) | C7: Autenticación y roles | D7: Producto | E7: 3 | F7: 5 | G7: =IF(OR(E7="",F7=""),"",E7*F7) | H7: =IF(G7="","",IF(G7>=15,"Alto",IF(G7>=8,"Medio","Bajo"))) | I7: Tabla de decisión rol × endpoint automatizada en cada build | J7: CP-023 a CP-025, CP-027 | K7: Controlado
A8: R-04 | B8: Sesión o CSRF mal configurados (sesión reutilizable, solicitudes forjadas) | C8: Autenticación y roles | D8: Producto | E8: 2 | F8: 5 | G8: =IF(OR(E8="",F8=""),"",E8*F8) | H8: =IF(G8="","",IF(G8>=15,"Alto",IF(G8>=8,"Medio","Bajo"))) | I8: Pruebas de cierre de sesión, cambio de id y token CSRF | J8: CP-019, CP-022, CP-028 | K8: Controlado
A9: R-05 | B9: La carga de históricos acepta negativos o duplicados, o convierte ausentes en 0 | C9: Históricos | D9: Producto | E9: 3 | F9: 4 | G9: =IF(OR(E9="",F9=""),"",E9*F9) | H9: =IF(G9="","",IF(G9>=15,"Alto",IF(G9>=8,"Medio","Bajo"))) | I9: Partición de equivalencia y valores límite sobre lotes | J9: CP-012 a CP-014 | K9: Abierto
A10: R-06 | B10: Una ejecución deja de explicar su resultado tras corregir el histórico | C10: Pronóstico | D10: Producto | E10: 2 | F10: 4 | G10: =IF(OR(E10="",F10=""),"",E10*F10) | H10: =IF(G10="","",IF(G10>=15,"Alto",IF(G10>=8,"Medio","Bajo"))) | I10: Transición de estados: ejecutar, corregir y volver a consultar | J10: CP-015 | K10: Abierto
A11: R-07 | B11: Industrial no valida a tiempo la tolerancia, la política de ceros y los permisos | C11: Transversal | D11: Proyecto | E11: 4 | F11: 4 | G11: =IF(OR(E11="",F11=""),"",E11*F11) | H11: =IF(G11="","",IF(G11>=15,"Alto",IF(G11>=8,"Medio","Bajo"))) | I11: Pedir la firma del Anexo B en el corte 1; marcar las reglas como "a acordar" | J11: — | K11: Abierto
A12: R-08 | B12: El cálculo de pronóstico e indicadores sigue sin implementar al iniciar el corte 2 (501) | C12: Pronóstico | D12: Proyecto | E12: 4 | F12: 4 | G12: =IF(OR(E12="",F12=""),"",E12*F12) | H12: =IF(G12="","",IF(G12>=15,"Alto",IF(G12>=8,"Medio","Bajo"))) | I12: Valores de referencia listos; el script de API reintenta los casos en cuanto exista el endpoint | J12: CP-001 a CP-015, CP-031, CP-032 | K12: Abierto
A13: R-09 | B13: Lentitud de las consultas con muchas observaciones | C13: Transversal | D13: Producto | E13: 2 | F13: 3 | G13: =IF(OR(E13="",F13=""),"",E13*F13) | H13: =IF(G13="","",IF(G13>=15,"Alto",IF(G13>=8,"Medio","Bajo"))) | I13: Prueba de carga con k6 en el corte 3 | J13: CP-033 | K13: Abierto
A14: R-10 | B14: Exposición de datos de la empresa o de credenciales en pruebas y evidencias | C14: Transversal | D14: Proyecto | E14: 2 | F14: 5 | G14: =IF(OR(E14="",F14=""),"",E14*F14) | H14: =IF(G14="","",IF(G14>=15,"Alto",IF(G14>=8,"Medio","Bajo"))) | I14: Series sintéticas o anonimizadas; .env fuera del repositorio; evidencias sin contraseñas | J14: CP-026, CP-029 | K14: Controlado
G15: =IF(OR(E15="",F15=""),"",E15*F15) | H15: =IF(G15="","",IF(G15>=15,"Alto",IF(G15>=8,"Medio","Bajo")))
G16: =IF(OR(E16="",F16=""),"",E16*F16) | H16: =IF(G16="","",IF(G16>=15,"Alto",IF(G16>=8,"Medio","Bajo")))
G17: =IF(OR(E17="",F17=""),"",E17*F17) | H17: =IF(G17="","",IF(G17>=15,"Alto",IF(G17>=8,"Medio","Bajo")))
G18: =IF(OR(E18="",F18=""),"",E18*F18) | H18: =IF(G18="","",IF(G18>=15,"Alto",IF(G18>=8,"Medio","Bajo")))
G19: =IF(OR(E19="",F19=""),"",E19*F19) | H19: =IF(G19="","",IF(G19>=15,"Alto",IF(G19>=8,"Medio","Bajo")))
G20: =IF(OR(E20="",F20=""),"",E20*F20) | H20: =IF(G20="","",IF(G20>=15,"Alto",IF(G20>=8,"Medio","Bajo")))
G21: =IF(OR(E21="",F21=""),"",E21*F21) | H21: =IF(G21="","",IF(G21>=15,"Alto",IF(G21>=8,"Medio","Bajo")))
G22: =IF(OR(E22="",F22=""),"",E22*F22) | H22: =IF(G22="","",IF(G22>=15,"Alto",IF(G22>=8,"Medio","Bajo")))
G23: =IF(OR(E23="",F23=""),"",E23*F23) | H23: =IF(G23="","",IF(G23>=15,"Alto",IF(G23>=8,"Medio","Bajo")))
G24: =IF(OR(E24="",F24=""),"",E24*F24) | H24: =IF(G24="","",IF(G24>=15,"Alto",IF(G24>=8,"Medio","Bajo")))
G25: =IF(OR(E25="",F25=""),"",E25*F25) | H25: =IF(G25="","",IF(G25>=15,"Alto",IF(G25>=8,"Medio","Bajo")))
G26: =IF(OR(E26="",F26=""),"",E26*F26) | H26: =IF(G26="","",IF(G26>=15,"Alto",IF(G26>=8,"Medio","Bajo")))
... G44: =IF(OR(E44="",F44=""),"",E44*F44) | H44: =IF(G44="","",IF(G44>=15,"Alto",IF(G44>=8,"Medio","Bajo")))

Sheet Listas
A1: Módulo | B1: Tipo | C1: Prioridad | D1: Nivel | E1: Técnica | F1: Veredicto | G1: Tipo de riesgo | H1: Escala 1-5
A2: Autenticación y roles | B2: Funcional | C2: Alta | D2: Unitaria | E2: Verificación numérica | F2: PENDIENTE | G2: Producto | H2: 1
A3: Históricos | B3: No funcional | C3: Media | D3: Integración | E3: Partición de equivalencia | F3: APROBADO | G3: Proyecto | H3: 2
A4: Pronóstico | C4: Baja | D4: Sistema/Funcional | E4: Valores límite | F4: FALLIDO | H4: 3
A5: Indicadores | D5: Aceptación | E5: Tabla de decisión | F5: BLOQUEADO | H5: 4
A6: Transversal | D6: Rendimiento | E6: Transición de estados | H6: 5
D7: Seguridad | E7: Caja blanca
D8: Usabilidad | E8: Basada en riesgo
E9: Exploratoria
A10: Hoja de apoyo: alimenta las listas desplegables. No la modifiques.
